[2022-09-04T16:21:18.424+0000] {taskinstance.py:1171} INFO - Dependencies all met for <TaskInstance: first_airflow_dag.process_datetime manual__2022-09-04T16:21:17.208561+00:00 [queued]>
[2022-09-04T16:21:18.430+0000] {taskinstance.py:1171} INFO - Dependencies all met for <TaskInstance: first_airflow_dag.process_datetime manual__2022-09-04T16:21:17.208561+00:00 [queued]>
[2022-09-04T16:21:18.431+0000] {taskinstance.py:1368} INFO - 
--------------------------------------------------------------------------------
[2022-09-04T16:21:18.432+0000] {taskinstance.py:1369} INFO - Starting attempt 1 of 1
[2022-09-04T16:21:18.433+0000] {taskinstance.py:1370} INFO - 
--------------------------------------------------------------------------------
[2022-09-04T16:21:18.442+0000] {taskinstance.py:1389} INFO - Executing <Task(PythonOperator): process_datetime> on 2022-09-04 16:21:17.208561+00:00
[2022-09-04T16:21:18.446+0000] {standard_task_runner.py:52} INFO - Started process 3100 to run task
[2022-09-04T16:21:18.449+0000] {standard_task_runner.py:79} INFO - Running: ['***', 'tasks', 'run', 'first_***_dag', 'process_datetime', 'manual__2022-09-04T16:21:17.208561+00:00', '--job-id', '46', '--raw', '--subdir', 'DAGS_FOLDER/first_dag.py', '--cfg-path', '/tmp/tmpfh81gay1', '--error-file', '/tmp/tmpy9l0t8pv']
[2022-09-04T16:21:18.451+0000] {standard_task_runner.py:80} INFO - Job 46: Subtask process_datetime
[2022-09-04T16:21:18.497+0000] {task_command.py:371} INFO - Running <TaskInstance: first_airflow_dag.process_datetime manual__2022-09-04T16:21:17.208561+00:00 [running]> on host c56acb3a0493
[2022-09-04T16:21:18.539+0000] {taskinstance.py:1583} INFO - Exporting the following env vars:
AIRFLOW_CTX_DAG_OWNER=***
AIRFLOW_CTX_DAG_ID=first_***_dag
AIRFLOW_CTX_TASK_ID=process_datetime
AIRFLOW_CTX_EXECUTION_DATE=2022-09-04T16:21:17.208561+00:00
AIRFLOW_CTX_TRY_NUMBER=1
AIRFLOW_CTX_DAG_RUN_ID=manual__2022-09-04T16:21:17.208561+00:00
[2022-09-04T16:21:18.546+0000] {taskinstance.py:1902} ERROR - Task failed with exception
Traceback (most recent call last):
  File "/home/airflow/.local/lib/python3.7/site-packages/airflow/operators/python.py", line 171, in execute
    return_value = self.execute_callable()
  File "/home/airflow/.local/lib/python3.7/site-packages/airflow/operators/python.py", line 189, in execute_callable
    return self.python_callable(*self.op_args, **self.op_kwargs)
  File "/opt/airflow/dags/first_dag.py", line 14, in process_datetime
    raise Exception('No datetime value.')
Exception: No datetime value.
[2022-09-04T16:21:18.553+0000] {taskinstance.py:1412} INFO - Marking task as FAILED. dag_id=first_***_dag, task_id=process_datetime, execution_date=20220904T162117, start_date=20220904T162118, end_date=20220904T162118
[2022-09-04T16:21:18.561+0000] {standard_task_runner.py:97} ERROR - Failed to execute job 46 for task process_datetime (No datetime value.; 3100)
[2022-09-04T16:21:18.581+0000] {local_task_job.py:156} INFO - Task exited with return code 1
[2022-09-04T16:21:18.601+0000] {local_task_job.py:279} INFO - 0 downstream tasks scheduled from follow-on schedule check
