[2022-09-04T16:27:01.660+0000] {taskinstance.py:1171} INFO - Dependencies all met for <TaskInstance: first_airflow_dag.save_datetime scheduled__2022-09-04T16:26:00+00:00 [queued]>
[2022-09-04T16:27:01.681+0000] {taskinstance.py:1171} INFO - Dependencies all met for <TaskInstance: first_airflow_dag.save_datetime scheduled__2022-09-04T16:26:00+00:00 [queued]>
[2022-09-04T16:27:01.684+0000] {taskinstance.py:1368} INFO - 
--------------------------------------------------------------------------------
[2022-09-04T16:27:01.684+0000] {taskinstance.py:1369} INFO - Starting attempt 1 of 1
[2022-09-04T16:27:01.686+0000] {taskinstance.py:1370} INFO - 
--------------------------------------------------------------------------------
[2022-09-04T16:27:01.704+0000] {taskinstance.py:1389} INFO - Executing <Task(PythonOperator): save_datetime> on 2022-09-04 16:26:00+00:00
[2022-09-04T16:27:01.718+0000] {standard_task_runner.py:52} INFO - Started process 3424 to run task
[2022-09-04T16:27:01.728+0000] {standard_task_runner.py:79} INFO - Running: ['***', 'tasks', 'run', 'first_***_dag', 'save_datetime', 'scheduled__2022-09-04T16:26:00+00:00', '--job-id', '59', '--raw', '--subdir', 'DAGS_FOLDER/first_dag.py', '--cfg-path', '/tmp/tmp_if0s6o5', '--error-file', '/tmp/tmpuweyinty']
[2022-09-04T16:27:01.732+0000] {standard_task_runner.py:80} INFO - Job 59: Subtask save_datetime
[2022-09-04T16:27:01.824+0000] {task_command.py:371} INFO - Running <TaskInstance: first_airflow_dag.save_datetime scheduled__2022-09-04T16:26:00+00:00 [running]> on host c56acb3a0493
[2022-09-04T16:27:01.886+0000] {taskinstance.py:1583} INFO - Exporting the following env vars:
AIRFLOW_CTX_DAG_OWNER=***
AIRFLOW_CTX_DAG_ID=first_***_dag
AIRFLOW_CTX_TASK_ID=save_datetime
AIRFLOW_CTX_EXECUTION_DATE=2022-09-04T16:26:00+00:00
AIRFLOW_CTX_TRY_NUMBER=1
AIRFLOW_CTX_DAG_RUN_ID=scheduled__2022-09-04T16:26:00+00:00
[2022-09-04T16:27:01.894+0000] {taskinstance.py:1902} ERROR - Task failed with exception
Traceback (most recent call last):
  File "/home/airflow/.local/lib/python3.7/site-packages/airflow/operators/python.py", line 171, in execute
    return_value = self.execute_callable()
  File "/home/airflow/.local/lib/python3.7/site-packages/airflow/operators/python.py", line 189, in execute_callable
    return self.python_callable(*self.op_args, **self.op_kwargs)
  File "/opt/airflow/dags/first_dag.py", line 30, in save_datetime
    raise Exception('No Processed dateime value')
Exception: No Processed dateime value
[2022-09-04T16:27:01.907+0000] {taskinstance.py:1412} INFO - Marking task as FAILED. dag_id=first_***_dag, task_id=save_datetime, execution_date=20220904T162600, start_date=20220904T162701, end_date=20220904T162701
[2022-09-04T16:27:01.920+0000] {standard_task_runner.py:97} ERROR - Failed to execute job 59 for task save_datetime (No Processed dateime value; 3424)
[2022-09-04T16:27:01.943+0000] {local_task_job.py:156} INFO - Task exited with return code 1
[2022-09-04T16:27:01.967+0000] {local_task_job.py:279} INFO - 0 downstream tasks scheduled from follow-on schedule check
