[2022-09-04T16:42:30.893+0000] {taskinstance.py:1171} INFO - Dependencies all met for <TaskInstance: first_airflow_dag.save_datetime manual__2022-09-04T16:42:27.454350+00:00 [queued]>
[2022-09-04T16:42:30.899+0000] {taskinstance.py:1171} INFO - Dependencies all met for <TaskInstance: first_airflow_dag.save_datetime manual__2022-09-04T16:42:27.454350+00:00 [queued]>
[2022-09-04T16:42:30.901+0000] {taskinstance.py:1368} INFO - 
--------------------------------------------------------------------------------
[2022-09-04T16:42:30.902+0000] {taskinstance.py:1369} INFO - Starting attempt 1 of 1
[2022-09-04T16:42:30.903+0000] {taskinstance.py:1370} INFO - 
--------------------------------------------------------------------------------
[2022-09-04T16:42:30.911+0000] {taskinstance.py:1389} INFO - Executing <Task(PythonOperator): save_datetime> on 2022-09-04 16:42:27.454350+00:00
[2022-09-04T16:42:30.916+0000] {standard_task_runner.py:52} INFO - Started process 115 to run task
[2022-09-04T16:42:30.920+0000] {standard_task_runner.py:79} INFO - Running: ['***', 'tasks', 'run', 'first_***_dag', 'save_datetime', 'manual__2022-09-04T16:42:27.454350+00:00', '--job-id', '8', '--raw', '--subdir', 'DAGS_FOLDER/first_dag.py', '--cfg-path', '/tmp/tmp2o1vvr4l', '--error-file', '/tmp/tmphogndef7']
[2022-09-04T16:42:30.922+0000] {standard_task_runner.py:80} INFO - Job 8: Subtask save_datetime
[2022-09-04T16:42:30.966+0000] {task_command.py:371} INFO - Running <TaskInstance: first_airflow_dag.save_datetime manual__2022-09-04T16:42:27.454350+00:00 [running]> on host a8d8517a6bff
[2022-09-04T16:42:31.007+0000] {taskinstance.py:1583} INFO - Exporting the following env vars:
AIRFLOW_CTX_DAG_OWNER=***
AIRFLOW_CTX_DAG_ID=first_***_dag
AIRFLOW_CTX_TASK_ID=save_datetime
AIRFLOW_CTX_EXECUTION_DATE=2022-09-04T16:42:27.454350+00:00
AIRFLOW_CTX_TRY_NUMBER=1
AIRFLOW_CTX_DAG_RUN_ID=manual__2022-09-04T16:42:27.454350+00:00
[2022-09-04T16:42:31.014+0000] {logging_mixin.py:115} INFO - [{'year': 2022, 'month': 'Sep', 'day': 4, 'time': '16:42:29', 'day_of_week': 'Sun'}]
[2022-09-04T16:42:31.023+0000] {taskinstance.py:1902} ERROR - Task failed with exception
Traceback (most recent call last):
  File "/home/airflow/.local/lib/python3.7/site-packages/airflow/operators/python.py", line 171, in execute
    return_value = self.execute_callable()
  File "/home/airflow/.local/lib/python3.7/site-packages/airflow/operators/python.py", line 189, in execute_callable
    return self.python_callable(*self.op_args, **self.op_kwargs)
  File "/opt/airflow/dags/first_dag.py", line 34, in save_datetime
    csv_path = Variable.get('first_dag_csv_path')
  File "/home/airflow/.local/lib/python3.7/site-packages/airflow/models/variable.py", line 138, in get
    raise KeyError(f'Variable {key} does not exist')
KeyError: 'Variable first_dag_csv_path does not exist'
[2022-09-04T16:42:31.033+0000] {taskinstance.py:1412} INFO - Marking task as FAILED. dag_id=first_***_dag, task_id=save_datetime, execution_date=20220904T164227, start_date=20220904T164230, end_date=20220904T164231
[2022-09-04T16:42:31.041+0000] {standard_task_runner.py:97} ERROR - Failed to execute job 8 for task save_datetime ('Variable first_dag_csv_path does not exist'; 115)
[2022-09-04T16:42:31.092+0000] {local_task_job.py:156} INFO - Task exited with return code 1
[2022-09-04T16:42:31.112+0000] {local_task_job.py:279} INFO - 0 downstream tasks scheduled from follow-on schedule check
