[2022-09-04T16:27:01.631+0000] {taskinstance.py:1171} INFO - Dependencies all met for <TaskInstance: first_airflow_dag.process_datetime scheduled__2022-09-04T16:26:00+00:00 [queued]>
[2022-09-04T16:27:01.642+0000] {taskinstance.py:1171} INFO - Dependencies all met for <TaskInstance: first_airflow_dag.process_datetime scheduled__2022-09-04T16:26:00+00:00 [queued]>
[2022-09-04T16:27:01.643+0000] {taskinstance.py:1368} INFO - 
--------------------------------------------------------------------------------
[2022-09-04T16:27:01.644+0000] {taskinstance.py:1369} INFO - Starting attempt 1 of 1
[2022-09-04T16:27:01.645+0000] {taskinstance.py:1370} INFO - 
--------------------------------------------------------------------------------
[2022-09-04T16:27:01.654+0000] {taskinstance.py:1389} INFO - Executing <Task(PythonOperator): process_datetime> on 2022-09-04 16:26:00+00:00
[2022-09-04T16:27:01.663+0000] {standard_task_runner.py:52} INFO - Started process 3423 to run task
[2022-09-04T16:27:01.666+0000] {standard_task_runner.py:79} INFO - Running: ['***', 'tasks', 'run', 'first_***_dag', 'process_datetime', 'scheduled__2022-09-04T16:26:00+00:00', '--job-id', '58', '--raw', '--subdir', 'DAGS_FOLDER/first_dag.py', '--cfg-path', '/tmp/tmpjvgdi2h5', '--error-file', '/tmp/tmpw_y1lb5l']
[2022-09-04T16:27:01.669+0000] {standard_task_runner.py:80} INFO - Job 58: Subtask process_datetime
[2022-09-04T16:27:01.776+0000] {task_command.py:371} INFO - Running <TaskInstance: first_airflow_dag.process_datetime scheduled__2022-09-04T16:26:00+00:00 [running]> on host c56acb3a0493
[2022-09-04T16:27:01.834+0000] {taskinstance.py:1583} INFO - Exporting the following env vars:
AIRFLOW_CTX_DAG_OWNER=***
AIRFLOW_CTX_DAG_ID=first_***_dag
AIRFLOW_CTX_TASK_ID=process_datetime
AIRFLOW_CTX_EXECUTION_DATE=2022-09-04T16:26:00+00:00
AIRFLOW_CTX_TRY_NUMBER=1
AIRFLOW_CTX_DAG_RUN_ID=scheduled__2022-09-04T16:26:00+00:00
[2022-09-04T16:27:01.844+0000] {taskinstance.py:1902} ERROR - Task failed with exception
Traceback (most recent call last):
  File "/home/airflow/.local/lib/python3.7/site-packages/airflow/operators/python.py", line 171, in execute
    return_value = self.execute_callable()
  File "/home/airflow/.local/lib/python3.7/site-packages/airflow/operators/python.py", line 189, in execute_callable
    return self.python_callable(*self.op_args, **self.op_kwargs)
  File "/opt/airflow/dags/first_dag.py", line 16, in process_datetime
    raise Exception('No datetime value.')
Exception: No datetime value.
[2022-09-04T16:27:01.854+0000] {taskinstance.py:1412} INFO - Marking task as FAILED. dag_id=first_***_dag, task_id=process_datetime, execution_date=20220904T162600, start_date=20220904T162701, end_date=20220904T162701
[2022-09-04T16:27:01.863+0000] {standard_task_runner.py:97} ERROR - Failed to execute job 58 for task process_datetime (No datetime value.; 3423)
[2022-09-04T16:27:01.880+0000] {local_task_job.py:156} INFO - Task exited with return code 1
[2022-09-04T16:27:01.909+0000] {local_task_job.py:279} INFO - 0 downstream tasks scheduled from follow-on schedule check
