[2022-09-04T16:20:11.283+0000] {taskinstance.py:1171} INFO - Dependencies all met for <TaskInstance: first_airflow_dag.process_datetime scheduled__2022-09-04T16:19:00+00:00 [queued]>
[2022-09-04T16:20:11.290+0000] {taskinstance.py:1171} INFO - Dependencies all met for <TaskInstance: first_airflow_dag.process_datetime scheduled__2022-09-04T16:19:00+00:00 [queued]>
[2022-09-04T16:20:11.291+0000] {taskinstance.py:1368} INFO - 
--------------------------------------------------------------------------------
[2022-09-04T16:20:11.293+0000] {taskinstance.py:1369} INFO - Starting attempt 1 of 1
[2022-09-04T16:20:11.294+0000] {taskinstance.py:1370} INFO - 
--------------------------------------------------------------------------------
[2022-09-04T16:20:11.303+0000] {taskinstance.py:1389} INFO - Executing <Task(PythonOperator): process_datetime> on 2022-09-04 16:19:00+00:00
[2022-09-04T16:20:11.308+0000] {standard_task_runner.py:52} INFO - Started process 3024 to run task
[2022-09-04T16:20:11.312+0000] {standard_task_runner.py:79} INFO - Running: ['***', 'tasks', 'run', 'first_***_dag', 'process_datetime', 'scheduled__2022-09-04T16:19:00+00:00', '--job-id', '40', '--raw', '--subdir', 'DAGS_FOLDER/first_dag.py', '--cfg-path', '/tmp/tmp6fi4234y', '--error-file', '/tmp/tmpxinf6zyw']
[2022-09-04T16:20:11.314+0000] {standard_task_runner.py:80} INFO - Job 40: Subtask process_datetime
[2022-09-04T16:20:11.371+0000] {task_command.py:371} INFO - Running <TaskInstance: first_airflow_dag.process_datetime scheduled__2022-09-04T16:19:00+00:00 [running]> on host c56acb3a0493
[2022-09-04T16:20:11.421+0000] {taskinstance.py:1583} INFO - Exporting the following env vars:
AIRFLOW_CTX_DAG_OWNER=***
AIRFLOW_CTX_DAG_ID=first_***_dag
AIRFLOW_CTX_TASK_ID=process_datetime
AIRFLOW_CTX_EXECUTION_DATE=2022-09-04T16:19:00+00:00
AIRFLOW_CTX_TRY_NUMBER=1
AIRFLOW_CTX_DAG_RUN_ID=scheduled__2022-09-04T16:19:00+00:00
[2022-09-04T16:20:11.430+0000] {taskinstance.py:1902} ERROR - Task failed with exception
Traceback (most recent call last):
  File "/home/airflow/.local/lib/python3.7/site-packages/airflow/operators/python.py", line 171, in execute
    return_value = self.execute_callable()
  File "/home/airflow/.local/lib/python3.7/site-packages/airflow/operators/python.py", line 189, in execute_callable
    return self.python_callable(*self.op_args, **self.op_kwargs)
  File "/opt/airflow/dags/first_dag.py", line 14, in process_datetime
    raise Exception('No datetime value')
Exception: No datetime value
[2022-09-04T16:20:11.439+0000] {taskinstance.py:1412} INFO - Marking task as FAILED. dag_id=first_***_dag, task_id=process_datetime, execution_date=20220904T161900, start_date=20220904T162011, end_date=20220904T162011
[2022-09-04T16:20:11.446+0000] {standard_task_runner.py:97} ERROR - Failed to execute job 40 for task process_datetime (No datetime value; 3024)
[2022-09-04T16:20:11.485+0000] {local_task_job.py:156} INFO - Task exited with return code 1
[2022-09-04T16:20:11.507+0000] {local_task_job.py:279} INFO - 0 downstream tasks scheduled from follow-on schedule check
