[2022-09-04T16:18:42.356+0000] {taskinstance.py:1171} INFO - Dependencies all met for <TaskInstance: first_airflow_dag.process_datetime manual__2022-09-04T16:18:40.800087+00:00 [queued]>
[2022-09-04T16:18:42.376+0000] {taskinstance.py:1171} INFO - Dependencies all met for <TaskInstance: first_airflow_dag.process_datetime manual__2022-09-04T16:18:40.800087+00:00 [queued]>
[2022-09-04T16:18:42.377+0000] {taskinstance.py:1368} INFO - 
--------------------------------------------------------------------------------
[2022-09-04T16:18:42.378+0000] {taskinstance.py:1369} INFO - Starting attempt 1 of 1
[2022-09-04T16:18:42.379+0000] {taskinstance.py:1370} INFO - 
--------------------------------------------------------------------------------
[2022-09-04T16:18:42.388+0000] {taskinstance.py:1389} INFO - Executing <Task(PythonOperator): process_datetime> on 2022-09-04 16:18:40.800087+00:00
[2022-09-04T16:18:42.393+0000] {standard_task_runner.py:52} INFO - Started process 2940 to run task
[2022-09-04T16:18:42.396+0000] {standard_task_runner.py:79} INFO - Running: ['***', 'tasks', 'run', 'first_***_dag', 'process_datetime', 'manual__2022-09-04T16:18:40.800087+00:00', '--job-id', '36', '--raw', '--subdir', 'DAGS_FOLDER/first_dag.py', '--cfg-path', '/tmp/tmpkk6k1bix', '--error-file', '/tmp/tmp5h9mbbou']
[2022-09-04T16:18:42.398+0000] {standard_task_runner.py:80} INFO - Job 36: Subtask process_datetime
[2022-09-04T16:18:42.453+0000] {task_command.py:371} INFO - Running <TaskInstance: first_airflow_dag.process_datetime manual__2022-09-04T16:18:40.800087+00:00 [running]> on host c56acb3a0493
[2022-09-04T16:18:42.505+0000] {taskinstance.py:1583} INFO - Exporting the following env vars:
AIRFLOW_CTX_DAG_OWNER=***
AIRFLOW_CTX_DAG_ID=first_***_dag
AIRFLOW_CTX_TASK_ID=process_datetime
AIRFLOW_CTX_EXECUTION_DATE=2022-09-04T16:18:40.800087+00:00
AIRFLOW_CTX_TRY_NUMBER=1
AIRFLOW_CTX_DAG_RUN_ID=manual__2022-09-04T16:18:40.800087+00:00
[2022-09-04T16:18:42.514+0000] {taskinstance.py:1902} ERROR - Task failed with exception
Traceback (most recent call last):
  File "/home/airflow/.local/lib/python3.7/site-packages/airflow/operators/python.py", line 171, in execute
    return_value = self.execute_callable()
  File "/home/airflow/.local/lib/python3.7/site-packages/airflow/operators/python.py", line 189, in execute_callable
    return self.python_callable(*self.op_args, **self.op_kwargs)
  File "/opt/airflow/dags/first_dag.py", line 14, in process_datetime
    raise Exception('No datetime value')
Exception: No datetime value
[2022-09-04T16:18:42.524+0000] {taskinstance.py:1412} INFO - Marking task as FAILED. dag_id=first_***_dag, task_id=process_datetime, execution_date=20220904T161840, start_date=20220904T161842, end_date=20220904T161842
[2022-09-04T16:18:42.534+0000] {standard_task_runner.py:97} ERROR - Failed to execute job 36 for task process_datetime (No datetime value; 2940)
[2022-09-04T16:18:42.568+0000] {local_task_job.py:156} INFO - Task exited with return code 1
[2022-09-04T16:18:42.593+0000] {local_task_job.py:279} INFO - 0 downstream tasks scheduled from follow-on schedule check
